Traceback (most recent call last):
  File "C:\Users\ashej\.virtualenvs\jupyter-books-WZpnkDri\Lib\site-packages\jupyter_cache\executors\utils.py", line 51, in single_nb_execution
    executenb(
  File "C:\Users\ashej\.virtualenvs\jupyter-books-WZpnkDri\Lib\site-packages\nbclient\client.py", line 1204, in execute
    return NotebookClient(nb=nb, resources=resources, km=km, **kwargs).execute()
           ^^^^^^^^^^^^^^^^^^^^^^^^^^^^^^^^^^^^^^^^^^^^^^^^^^^^^^^^^^^^^^^^^^^^^
  File "C:\Users\ashej\.virtualenvs\jupyter-books-WZpnkDri\Lib\site-packages\nbclient\util.py", line 84, in wrapped
    return just_run(coro(*args, **kwargs))
           ^^^^^^^^^^^^^^^^^^^^^^^^^^^^^^^
  File "C:\Users\ashej\.virtualenvs\jupyter-books-WZpnkDri\Lib\site-packages\nbclient\util.py", line 62, in just_run
    return loop.run_until_complete(coro)
           ^^^^^^^^^^^^^^^^^^^^^^^^^^^^^
  File "C:\Users\ashej\AppData\Local\Programs\Python\Python311\Lib\asyncio\base_events.py", line 653, in run_until_complete
    return future.result()
           ^^^^^^^^^^^^^^^
  File "C:\Users\ashej\AppData\Local\Programs\Python\Python311\Lib\contextlib.py", line 222, in __aexit__
    await self.gen.athrow(typ, value, traceback)
  File "C:\Users\ashej\.virtualenvs\jupyter-books-WZpnkDri\Lib\site-packages\nbclient\client.py", line 608, in async_setup_kernel
    yield
  File "C:\Users\ashej\.virtualenvs\jupyter-books-WZpnkDri\Lib\site-packages\nbclient\client.py", line 663, in async_execute
    await self.async_execute_cell(
  File "C:\Users\ashej\.virtualenvs\jupyter-books-WZpnkDri\Lib\site-packages\nbclient\client.py", line 965, in async_execute_cell
    await self._check_raise_for_error(cell, cell_index, exec_reply)
  File "C:\Users\ashej\.virtualenvs\jupyter-books-WZpnkDri\Lib\site-packages\nbclient\client.py", line 862, in _check_raise_for_error
    raise CellExecutionError.from_cell_and_msg(cell, exec_reply_content)
nbclient.exceptions.CellExecutionError: An error occurred while executing the following cell:
------------------
from numpy import random
import matplotlib.pyplot as plt

x = random.randint(10, size=(10))
y = random.randint(10, size=(10))

plt.scatter(x, y)
img_fn = 'example.png'
plt.savefig(img_fn)

img2 = Image(filename=img_fn, alt="another image")
# _repr_html_() returns None
assert img2._repr_html_() == None

------------------

[1;31m---------------------------------------------------------------------------[0m
[1;31mNameError[0m                                 Traceback (most recent call last)
Cell [1;32mIn[5], line 11[0m
[0;32m      8[0m img_fn [38;5;241m=[39m [38;5;124m'[39m[38;5;124mexample.png[39m[38;5;124m'[39m
[0;32m      9[0m plt[38;5;241m.[39msavefig(img_fn)
[1;32m---> 11[0m img2 [38;5;241m=[39m [43mImage[49m(filename[38;5;241m=[39mimg_fn, alt[38;5;241m=[39m[38;5;124m"[39m[38;5;124manother image[39m[38;5;124m"[39m)
[0;32m     12[0m [38;5;66;03m# _repr_html_() returns None[39;00m
[0;32m     13[0m [38;5;28;01massert[39;00m img2[38;5;241m.[39m_repr_html_() [38;5;241m==[39m [38;5;28;01mNone[39;00m

[1;31mNameError[0m: name 'Image' is not defined
NameError: name 'Image' is not defined

