Traceback (most recent call last):
  File "C:\Users\ashej\PythonTools\anaconda3\envs\jupyter-book-env\lib\site-packages\jupyter_cache\executors\utils.py", line 51, in single_nb_execution
    executenb(
  File "C:\Users\ashej\PythonTools\anaconda3\envs\jupyter-book-env\lib\site-packages\nbclient\client.py", line 1204, in execute
    return NotebookClient(nb=nb, resources=resources, km=km, **kwargs).execute()
  File "C:\Users\ashej\PythonTools\anaconda3\envs\jupyter-book-env\lib\site-packages\nbclient\util.py", line 84, in wrapped
    return just_run(coro(*args, **kwargs))
  File "C:\Users\ashej\PythonTools\anaconda3\envs\jupyter-book-env\lib\site-packages\nbclient\util.py", line 62, in just_run
    return loop.run_until_complete(coro)
  File "C:\Users\ashej\PythonTools\anaconda3\envs\jupyter-book-env\lib\asyncio\base_events.py", line 649, in run_until_complete
    return future.result()
  File "C:\Users\ashej\PythonTools\anaconda3\envs\jupyter-book-env\lib\site-packages\nbclient\client.py", line 663, in async_execute
    await self.async_execute_cell(
  File "C:\Users\ashej\PythonTools\anaconda3\envs\jupyter-book-env\lib\site-packages\nbclient\client.py", line 965, in async_execute_cell
    await self._check_raise_for_error(cell, cell_index, exec_reply)
  File "C:\Users\ashej\PythonTools\anaconda3\envs\jupyter-book-env\lib\site-packages\nbclient\client.py", line 862, in _check_raise_for_error
    raise CellExecutionError.from_cell_and_msg(cell, exec_reply_content)
nbclient.exceptions.CellExecutionError: An error occurred while executing the following cell:
------------------
import matplotlib.pyplot as plt
import seaborn as sns

A = df[df['type'] == 'Iris-setosa']['petal-length']
B = df[df['type'] == 'Iris-versicolor']['petal-length']
C = df[df['type'] == 'Iris-virginica']['petal-length']

sns.histplot(A, color = 'red', kde=True, bins = 10)
sns.histplot(B, color ='blue', kde=True, bins = 10)
sns.histplot(C, color = 'green', kde=True, bins = 10)
plt.show()
------------------

[1;31m---------------------------------------------------------------------------[0m
[1;31mModuleNotFoundError[0m                       Traceback (most recent call last)
Cell [1;32mIn[7], line 2[0m
[0;32m      1[0m [38;5;28;01mimport[39;00m [38;5;21;01mmatplotlib[39;00m[38;5;21;01m.[39;00m[38;5;21;01mpyplot[39;00m [38;5;28;01mas[39;00m [38;5;21;01mplt[39;00m
[1;32m----> 2[0m [38;5;28;01mimport[39;00m [38;5;21;01mseaborn[39;00m [38;5;28;01mas[39;00m [38;5;21;01msns[39;00m
[0;32m      4[0m A [38;5;241m=[39m df[df[[38;5;124m'[39m[38;5;124mtype[39m[38;5;124m'[39m] [38;5;241m==[39m [38;5;124m'[39m[38;5;124mIris-setosa[39m[38;5;124m'[39m][[38;5;124m'[39m[38;5;124mpetal-length[39m[38;5;124m'[39m]
[0;32m      5[0m B [38;5;241m=[39m df[df[[38;5;124m'[39m[38;5;124mtype[39m[38;5;124m'[39m] [38;5;241m==[39m [38;5;124m'[39m[38;5;124mIris-versicolor[39m[38;5;124m'[39m][[38;5;124m'[39m[38;5;124mpetal-length[39m[38;5;124m'[39m]

[1;31mModuleNotFoundError[0m: No module named 'seaborn'
ModuleNotFoundError: No module named 'seaborn'

