Traceback (most recent call last):
  File "C:\Users\ashej\.virtualenvs\jupyter-books-WZpnkDri\Lib\site-packages\jupyter_cache\executors\utils.py", line 51, in single_nb_execution
    executenb(
  File "C:\Users\ashej\.virtualenvs\jupyter-books-WZpnkDri\Lib\site-packages\nbclient\client.py", line 1204, in execute
    return NotebookClient(nb=nb, resources=resources, km=km, **kwargs).execute()
           ^^^^^^^^^^^^^^^^^^^^^^^^^^^^^^^^^^^^^^^^^^^^^^^^^^^^^^^^^^^^^^^^^^^^^
  File "C:\Users\ashej\.virtualenvs\jupyter-books-WZpnkDri\Lib\site-packages\nbclient\util.py", line 84, in wrapped
    return just_run(coro(*args, **kwargs))
           ^^^^^^^^^^^^^^^^^^^^^^^^^^^^^^^
  File "C:\Users\ashej\.virtualenvs\jupyter-books-WZpnkDri\Lib\site-packages\nbclient\util.py", line 62, in just_run
    return loop.run_until_complete(coro)
           ^^^^^^^^^^^^^^^^^^^^^^^^^^^^^
  File "C:\Users\ashej\AppData\Local\Programs\Python\Python311\Lib\asyncio\base_events.py", line 653, in run_until_complete
    return future.result()
           ^^^^^^^^^^^^^^^
  File "C:\Users\ashej\AppData\Local\Programs\Python\Python311\Lib\contextlib.py", line 222, in __aexit__
    await self.gen.athrow(typ, value, traceback)
  File "C:\Users\ashej\.virtualenvs\jupyter-books-WZpnkDri\Lib\site-packages\nbclient\client.py", line 608, in async_setup_kernel
    yield
  File "C:\Users\ashej\.virtualenvs\jupyter-books-WZpnkDri\Lib\site-packages\nbclient\client.py", line 663, in async_execute
    await self.async_execute_cell(
  File "C:\Users\ashej\.virtualenvs\jupyter-books-WZpnkDri\Lib\site-packages\nbclient\client.py", line 965, in async_execute_cell
    await self._check_raise_for_error(cell, cell_index, exec_reply)
  File "C:\Users\ashej\.virtualenvs\jupyter-books-WZpnkDri\Lib\site-packages\nbclient\client.py", line 862, in _check_raise_for_error
    raise CellExecutionError.from_cell_and_msg(cell, exec_reply_content)
nbclient.exceptions.CellExecutionError: An error occurred while executing the following cell:
------------------
y = df[['type']].copy()
X = df.drop(columns=['type'])

from IPython.display import display_html 
X_styler = X.head(5).style.set_table_attributes("style='display:inline'").set_caption('Independents variables')
y_styler = y.head(5).style.set_table_attributes("style='display:inline'").set_caption('Dependents variables')
space = "\xa0" * 10 #space between columns
display_html(X_styler._repr_html_()+ space  + y_styler._repr_html_(), raw=True)
#TODO add note about having BOTH as arrays OR dataframes? check compatiability
------------------

[1;31m---------------------------------------------------------------------------[0m
[1;31mNameError[0m                                 Traceback (most recent call last)
Cell [1;32mIn[1], line 1[0m
[1;32m----> 1[0m y [38;5;241m=[39m [43mdf[49m[[[38;5;124m'[39m[38;5;124mtype[39m[38;5;124m'[39m]][38;5;241m.[39mcopy()
[0;32m      2[0m X [38;5;241m=[39m df[38;5;241m.[39mdrop(columns[38;5;241m=[39m[[38;5;124m'[39m[38;5;124mtype[39m[38;5;124m'[39m])
[0;32m      4[0m [38;5;28;01mfrom[39;00m [38;5;21;01mIPython[39;00m[38;5;21;01m.[39;00m[38;5;21;01mdisplay[39;00m [38;5;28;01mimport[39;00m display_html 

[1;31mNameError[0m: name 'df' is not defined
NameError: name 'df' is not defined

