Traceback (most recent call last):
  File "C:\Users\ashej\.virtualenvs\jupyter-books-WZpnkDri\Lib\site-packages\jupyter_cache\executors\utils.py", line 58, in single_nb_execution
    executenb(
  File "C:\Users\ashej\.virtualenvs\jupyter-books-WZpnkDri\Lib\site-packages\nbclient\client.py", line 1204, in execute
    return NotebookClient(nb=nb, resources=resources, km=km, **kwargs).execute()
           ^^^^^^^^^^^^^^^^^^^^^^^^^^^^^^^^^^^^^^^^^^^^^^^^^^^^^^^^^^^^^^^^^^^^^
  File "C:\Users\ashej\.virtualenvs\jupyter-books-WZpnkDri\Lib\site-packages\nbclient\util.py", line 84, in wrapped
    return just_run(coro(*args, **kwargs))
           ^^^^^^^^^^^^^^^^^^^^^^^^^^^^^^^
  File "C:\Users\ashej\.virtualenvs\jupyter-books-WZpnkDri\Lib\site-packages\nbclient\util.py", line 62, in just_run
    return loop.run_until_complete(coro)
           ^^^^^^^^^^^^^^^^^^^^^^^^^^^^^
  File "C:\Users\ashej\AppData\Local\Programs\Python\Python311\Lib\asyncio\base_events.py", line 653, in run_until_complete
    return future.result()
           ^^^^^^^^^^^^^^^
  File "C:\Users\ashej\AppData\Local\Programs\Python\Python311\Lib\contextlib.py", line 222, in __aexit__
    await self.gen.athrow(typ, value, traceback)
  File "C:\Users\ashej\.virtualenvs\jupyter-books-WZpnkDri\Lib\site-packages\nbclient\client.py", line 608, in async_setup_kernel
    yield
  File "C:\Users\ashej\.virtualenvs\jupyter-books-WZpnkDri\Lib\site-packages\nbclient\client.py", line 663, in async_execute
    await self.async_execute_cell(
  File "C:\Users\ashej\.virtualenvs\jupyter-books-WZpnkDri\Lib\site-packages\nbclient\client.py", line 965, in async_execute_cell
    await self._check_raise_for_error(cell, cell_index, exec_reply)
  File "C:\Users\ashej\.virtualenvs\jupyter-books-WZpnkDri\Lib\site-packages\nbclient\client.py", line 862, in _check_raise_for_error
    raise CellExecutionError.from_cell_and_msg(cell, exec_reply_content)
nbclient.exceptions.CellExecutionError: An error occurred while executing the following cell:
------------------
from IPython.display import Image
plot = num_types.plot.bar(color=['red','blue','green'],rot=0)
plot.metadata['Title'] = 'Alt Text'
------------------

[1;31m---------------------------------------------------------------------------[0m
[1;31mAttributeError[0m                            Traceback (most recent call last)
Cell [1;32mIn[4], line 3[0m
[0;32m      1[0m [38;5;28;01mfrom[39;00m [38;5;21;01mIPython[39;00m[38;5;21;01m.[39;00m[38;5;21;01mdisplay[39;00m [38;5;28;01mimport[39;00m Image
[0;32m      2[0m plot [38;5;241m=[39m num_types[38;5;241m.[39mplot[38;5;241m.[39mbar(color[38;5;241m=[39m[[38;5;124m'[39m[38;5;124mred[39m[38;5;124m'[39m,[38;5;124m'[39m[38;5;124mblue[39m[38;5;124m'[39m,[38;5;124m'[39m[38;5;124mgreen[39m[38;5;124m'[39m],rot[38;5;241m=[39m[38;5;241m0[39m)
[1;32m----> 3[0m [43mplot[49m[38;5;241;43m.[39;49m[43mmetadata[49m[[38;5;124m'[39m[38;5;124mTitle[39m[38;5;124m'[39m] [38;5;241m=[39m [38;5;124m'[39m[38;5;124mAlt Text[39m[38;5;124m'[39m

[1;31mAttributeError[0m: 'AxesSubplot' object has no attribute 'metadata'
AttributeError: 'AxesSubplot' object has no attribute 'metadata'

