Traceback (most recent call last):
  File "C:\Users\ashej\.virtualenvs\jupyter-books-WZpnkDri\Lib\site-packages\jupyter_cache\executors\utils.py", line 58, in single_nb_execution
    executenb(
  File "C:\Users\ashej\.virtualenvs\jupyter-books-WZpnkDri\Lib\site-packages\nbclient\client.py", line 1204, in execute
    return NotebookClient(nb=nb, resources=resources, km=km, **kwargs).execute()
           ^^^^^^^^^^^^^^^^^^^^^^^^^^^^^^^^^^^^^^^^^^^^^^^^^^^^^^^^^^^^^^^^^^^^^
  File "C:\Users\ashej\.virtualenvs\jupyter-books-WZpnkDri\Lib\site-packages\nbclient\util.py", line 84, in wrapped
    return just_run(coro(*args, **kwargs))
           ^^^^^^^^^^^^^^^^^^^^^^^^^^^^^^^
  File "C:\Users\ashej\.virtualenvs\jupyter-books-WZpnkDri\Lib\site-packages\nbclient\util.py", line 62, in just_run
    return loop.run_until_complete(coro)
           ^^^^^^^^^^^^^^^^^^^^^^^^^^^^^
  File "C:\Users\ashej\AppData\Local\Programs\Python\Python311\Lib\asyncio\base_events.py", line 653, in run_until_complete
    return future.result()
           ^^^^^^^^^^^^^^^
  File "C:\Users\ashej\AppData\Local\Programs\Python\Python311\Lib\contextlib.py", line 222, in __aexit__
    await self.gen.athrow(typ, value, traceback)
  File "C:\Users\ashej\.virtualenvs\jupyter-books-WZpnkDri\Lib\site-packages\nbclient\client.py", line 608, in async_setup_kernel
    yield
  File "C:\Users\ashej\.virtualenvs\jupyter-books-WZpnkDri\Lib\site-packages\nbclient\client.py", line 663, in async_execute
    await self.async_execute_cell(
  File "C:\Users\ashej\.virtualenvs\jupyter-books-WZpnkDri\Lib\site-packages\nbclient\client.py", line 965, in async_execute_cell
    await self._check_raise_for_error(cell, cell_index, exec_reply)
  File "C:\Users\ashej\.virtualenvs\jupyter-books-WZpnkDri\Lib\site-packages\nbclient\client.py", line 862, in _check_raise_for_error
    raise CellExecutionError.from_cell_and_msg(cell, exec_reply_content)
nbclient.exceptions.CellExecutionError: An error occurred while executing the following cell:
------------------
plot1 = num_types.plot.bar(color=['red','blue','green'],rot=0)

import matplotlib.pyplot as plt
from IPython.display import display, HTML
import os 


def plot_with_alt_text(plot, alt_text =''):
     plt.savefig('output_plot.png')
     plt.close()
     cwd = os.getcwd() #returns current working directory
     dir_path = "output_plot.png"
     display(HTML(f'<img src="{dir_path}" alt="{alt_text}">'))

plot_with_alt_text(plot1, 'test alt')
cwd
------------------

[1;31m---------------------------------------------------------------------------[0m
[1;31mNameError[0m                                 Traceback (most recent call last)
Cell [1;32mIn[5], line 16[0m
[0;32m     13[0m      display(HTML([38;5;124mf[39m[38;5;124m'[39m[38;5;124m<img src=[39m[38;5;124m"[39m[38;5;132;01m{[39;00mdir_path[38;5;132;01m}[39;00m[38;5;124m"[39m[38;5;124m alt=[39m[38;5;124m"[39m[38;5;132;01m{[39;00malt_text[38;5;132;01m}[39;00m[38;5;124m"[39m[38;5;124m>[39m[38;5;124m'[39m))
[0;32m     15[0m plot_with_alt_text(plot1, [38;5;124m'[39m[38;5;124mtest alt[39m[38;5;124m'[39m)
[1;32m---> 16[0m [43mcwd[49m

[1;31mNameError[0m: name 'cwd' is not defined
NameError: name 'cwd' is not defined

